Workbook

Sheet tp
B1: Identificación del gobierno nacional | I1: Puntaje por pilar | L1: Puntaje por dimensión | O1: Nivel de desarrollo según fuentes secundarias | S1: Puntaje admisible en áreas temáticas destacadas
A2: Ranking | B2: ISO3 | C2: Country | D2: Pais | E2: GIRAI_region | F2: NU_region | G2: UN_subregion | H2: GIRAI | I2: mng | J2: ag | K2: ane | L2: ddhh | M2: gob | N2: cap | O2: sec_mng | P2: sec_ag | Q2: sec_ane | R2: Dimensión mejor puntuada | S2: p70_sesgo | T2: p70_infancia | U2: p70_divers | V2: p70_datpers | W2: p70_genero | X2: p70_suphum | Y2: p70_laboral | Z2: p70_segu | AA2: p70_transp | AB2: areas_mng | AC2: areas_ag | AD2: areas_parlam | AE2: areas_concient | AF2: areas_ane | AG2: academia | AH2: tipo_academia_en | AI2: tipo_academia_es | AJ2: privado | AK2: tipo_privado_en | AL2: tipo_privado_es
A3: 135 | B3: AFG | C3: Afghanistan | D3: Afganistán | E3: Asia y Oceanía | F3: Asia | G3: Asia Meridional | H3: 0.57423038 | I3: 0 | J3: 1.435576 | K3: 0 | L3: 0 | M3: 0 | N3: 3.6366667 | O3: Muy bajo | P3: Muy bajo | Q3: Muy bajo | R3: =XLOOKUP(max(L3:N3),L3:N3,$L$2:$N$2,"",0) -> cap | S3: =IFERROR(__xludf.DUMMYFUNCTION("IF(query(Data!A:M,CONCATENATE(""select Col13 where Col1 = '"",C3,""' and Col8 = 'Bias and Unfair Discrimination'""),0)>70,1,0)"),"#REF!") -> #REF! | T3: =IFERROR(__xludf.DUMMYFUNCTION("IF(query(Data!A:M,CONCATENATE(""select Col13 where Col1 = '"",C3,""' and Col8 = 'Childrens Rights'""),0)>70,1,0)"),"#REF!") -> #REF! | U3: =IFERROR(__xludf.DUMMYFUNCTION("IF(query(Data!A:M,CONCATENATE(""select Col13 where Col1 = '"",C3,""' and Col8 = 'Cultural and Linguistic Diversity'""),0)>70,1,0)"),"#REF!") -> #REF! | V3: =IFERROR(__xludf.DUMMYFUNCTION("IF(query(Data!A:M,CONCATENATE(""select Col13 where Col1 = '"",C3,""' and Col8 = 'Data Protection and Privacy'""),0)>70,1,0)"),"#REF!") -> #REF! | W3: =IFERROR(__xludf.DUMMYFUNCTION("IF(query(Data!A:M,CONCATENATE(""select Col13 where Col1 = '"",C3,""' and Col8 = 'Gender Equality'""),0)>70,1,0)"),"#REF!") -> #REF! | X3: =IFERROR(__xludf.DUMMYFUNCTION("IF(query(Data!A:M,CONCATENATE(""select Col13 where Col1 = '"",C3,""' and Col8 = 'Human Oversight and Determination'""),0)>70,1,0)"),"#REF!") -> #REF! | Y3: =IFERROR(__xludf.DUMMYFUNCTION("IF(query(Data!A:M,CONCATENATE(""select Col13 where Col1 = '"",C3,""' and Col8 = 'Labour Protection and Right to Work'""),0)>70,1,0)"),"#REF!") -> #REF! | Z3: =IFERROR(__xludf.DUMMYFUNCTION("IF(query(Data!A:M,CONCATENATE(""select Col13 where Col1 = '"",C3,""' and Col8 = 'Safety, Accuracy and Reliability'""),0)>70,1,0)"),"#REF!") -> #REF! | AA3: =IFERROR(__xludf.DUMMYFUNCTION("IF(query(Data!A:M,CONCATENATE(""select Col13 where Col1 = '"",C3,""' and Col8 = 'Transparency and Explainability'""),0)>70,1,0)"),"#REF!") -> #REF! | AB3: =COUNTIFS(Data!AF:AF,"1",Data!A:A,C3) -> 0 | AC3: =COUNTIFS(Data!X:X,">0",Data!A:A,C3) -> 0 | AD3: =COUNTIFS(Data!AJ:AJ,"12",Data!A:A,C3) -> 0 | AE3: =COUNTIFS(Data!AJ:AJ,"17",Data!A:A,C3) -> 0 | AF3: =COUNTIFS(Data!Y:Y,">0",Data!A:A,C3) -> 0 | AG3: =IF(COUNTIFS(Data!AO:AO,"1",Data!A:A,C3)>0,"Sí","No") -> No | AH3: =IFERROR(__xludf.DUMMYFUNCTION("IFERROR(query(query(Data!A:BS,CONCATENATE(""select Col50, count(Col49) where Col1 = '"",C3,""' group by Col50"")), CONCATENATE(""select Col1 where Col2 = "",query(query(query(Data!A:BS,CONCATENATE(""select Col50, count(Col49) where Col1 = '"",C3,""' and C"&"ol50 <> 'Other' and Col50 is not null group by Col50"")),""select max(Col2)"",0),""Select *"",0),"" limit 1""),0))"),"") | AI3: =IFERROR(VLOOKUP(AH3,ref!$A:$B,2,FALSE),"") | AJ3: =IF(COUNTIFS(Data!BI:BI,"1",Data!A:A,C3)>0,"Sí","No") -> No | AK3: =IFERROR(__xludf.DUMMYFUNCTION("IFERROR(query(query(Data!A:BS,CONCATENATE(""select Col70, count(Col69) where Col1 = '"",C3,""' group by Col70"")), CONCATENATE(""select Col1 where Col2 = "",query(query(query(Data!A:BS,CONCATENATE(""select Col70, count(Col69) where Col1 = '"",C3,""' and C"&"ol70 <> 'Other' and Col70 is not null group by Col70"")),""select max(Col2)"",0),""Select *"",0),"" limit 1""),0))"),"") | AL3: =IFERROR(VLOOKUP(AK3,ref!$A:$B,2,FALSE),"")
A4: 96 | B4: ALB | C4: Albania | D4: Albania | E4: Europa | F4: Europa | G4: Europa del Sur | H4: 4.0646206 | I4: 3.382572 | J4: 6.0731133 | K4: 1.4117325 | L4: 0.76642857 | M4: 0 | N4: 23.954333 | O4: Alto | P4: Alto | Q4: Alto | R4: =XLOOKUP(max(L4:N4),L4:N4,$L$2:$N$2,"",0) -> cap | S4: =IFERROR(__xludf.DUMMYFUNCTION("IF(query(Data!A:M,CONCATENATE(""select Col13 where Col1 = '"",C4,""' and Col8 = 'Bias and Unfair Discrimination'""),0)>70,1,0)"),"#REF!") -> #REF! | T4: =IFERROR(__xludf.DUMMYFUNCTION("IF(query(Data!A:M,CONCATENATE(""select Col13 where Col1 = '"",C4,""' and Col8 = 'Childrens Rights'""),0)>70,1,0)"),"#REF!") -> #REF! | U4: =IFERROR(__xludf.DUMMYFUNCTION("IF(query(Data!A:M,CONCATENATE(""select Col13 where Col1 = '"",C4,""' and Col8 = 'Cultural and Linguistic Diversity'""),0)>70,1,0)"),"#REF!") -> #REF! | V4: =IFERROR(__xludf.DUMMYFUNCTION("IF(query(Data!A:M,CONCATENATE(""select Col13 where Col1 = '"",C4,""' and Col8 = 'Data Protection and Privacy'""),0)>70,1,0)"),"#REF!") -> #REF! | W4: =IFERROR(__xludf.DUMMYFUNCTION("IF(query(Data!A:M,CONCATENATE(""select Col13 where Col1 = '"",C4,""' and Col8 = 'Gender Equality'""),0)>70,1,0)"),"#REF!") -> #REF! | X4: =IFERROR(__xludf.DUMMYFUNCTION("IF(query(Data!A:M,CONCATENATE(""select Col13 where Col1 = '"",C4,""' and Col8 = 'Human Oversight and Determination'""),0)>70,1,0)"),"#REF!") -> #REF! | Y4: =IFERROR(__xludf.DUMMYFUNCTION("IF(query(Data!A:M,CONCATENATE(""select Col13 where Col1 = '"",C4,""' and Col8 = 'Labour Protection and Right to Work'""),0)>70,1,0)"),"#REF!") -> #REF! | Z4: =IFERROR(__xludf.DUMMYFUNCTION("IF(query(Data!A:M,CONCATENATE(""select Col13 where Col1 = '"",C4,""' and Col8 = 'Safety, Accuracy and Reliability'""),0)>70,1,0)"),"#REF!") -> #REF! | AA4: =IFERROR(__xludf.DUMMYFUNCTION("IF(query(Data!A:M,CONCATENATE(""select Col13 where Col1 = '"",C4,""' and Col8 = 'Transparency and Explainability'""),0)>70,1,0)"),"#REF!") -> #REF! | AB4: =COUNTIFS(Data!AF:AF,"1",Data!A:A,C4) -> 0 | AC4: =COUNTIFS(Data!X:X,">0",Data!A:A,C4) -> 0 | AD4: =COUNTIFS(Data!AJ:AJ,"12",Data!A:A,C4) -> 0 | AE4: =COUNTIFS(Data!AJ:AJ,"17",Data!A:A,C4) -> 0 | AF4: =COUNTIFS(Data!Y:Y,">0",Data!A:A,C4) -> 0 | AG4: =IF(COUNTIFS(Data!AO:AO,"1",Data!A:A,C4)>0,"Sí","No") -> No | AH4: =IFERROR(__xludf.DUMMYFUNCTION("IFERROR(query(query(Data!A:BS,CONCATENATE(""select Col50, count(Col49) where Col1 = '"",C4,""' group by Col50"")), CONCATENATE(""select Col1 where Col2 = "",query(query(query(Data!A:BS,CONCATENATE(""select Col50, count(Col49) where Col1 = '"",C4,""' and C"&"ol50 <> 'Other' and Col50 is not null group by Col50"")),""select max(Col2)"",0),""Select *"",0),"" limit 1""),0))"),"") | AI4: =IFERROR(VLOOKUP(AH4,ref!$A:$B,2,FALSE),"") | AJ4: =IF(COUNTIFS(Data!BI:BI,"1",Data!A:A,C4)>0,"Sí","No") -> No | AK4: =IFERROR(__xludf.DUMMYFUNCTION("IFERROR(query(query(Data!A:BS,CONCATENATE(""select Col70, count(Col69) where Col1 = '"",C4,""' group by Col70"")), CONCATENATE(""select Col1 where Col2 = "",query(query(query(Data!A:BS,CONCATENATE(""select Col70, count(Col69) where Col1 = '"",C4,""' and C"&"ol70 <> 'Other' and Col70 is not null group by Col70"")),""select max(Col2)"",0),""Select *"",0),"" limit 1""),0))"),"") | AL4: =IFERROR(VLOOKUP(AK4,ref!$A:$B,2,FALSE),"")
A5: 2 | B5: DEU | C5: Germany | D5: Alemania | E5: Europa | F5: Europa | G5: Europa Occidental | H5: 82.77013 | I5: 72.687023 | J5: 92.996525 | K5: 82.483553 | L5: 80.301571 | M5: 90.936222 | N5: 64.032 | O5: Muy alto | P5: Muy alto | Q5: Muy alto | R5: =XLOOKUP(max(L5:N5),L5:N5,$L$2:$N$2,"",0) -> gob | S5: =IFERROR(__xludf.DUMMYFUNCTION("IF(query(Data!A:M,CONCATENATE(""select Col13 where Col1 = '"",C5,""' and Col8 = 'Bias and Unfair Discrimination'""),0)>70,1,0)"),"#REF!") -> #REF! | T5: =IFERROR(__xludf.DUMMYFUNCTION("IF(query(Data!A:M,CONCATENATE(""select Col13 where Col1 = '"",C5,""' and Col8 = 'Childrens Rights'""),0)>70,1,0)"),"#REF!") -> #REF! | U5: =IFERROR(__xludf.DUMMYFUNCTION("IF(query(Data!A:M,CONCATENATE(""select Col13 where Col1 = '"",C5,""' and Col8 = 'Cultural and Linguistic Diversity'""),0)>70,1,0)"),"#REF!") -> #REF! | V5: =IFERROR(__xludf.DUMMYFUNCTION("IF(query(Data!A:M,CONCATENATE(""select Col13 where Col1 = '"",C5,""' and Col8 = 'Data Protection and Privacy'""),0)>70,1,0)"),"#REF!") -> #REF! | W5: =IFERROR(__xludf.DUMMYFUNCTION("IF(query(Data!A:M,CONCATENATE(""select Col13 where Col1 = '"",C5,""' and Col8 = 'Gender Equality'""),0)>70,1,0)"),"#REF!") -> #REF! | X5: =IFERROR(__xludf.DUMMYFUNCTION("IF(query(Data!A:M,CONCATENATE(""select Col13 where Col1 = '"",C5,""' and Col8 = 'Human Oversight and Determination'""),0)>70,1,0)"),"#REF!") -> #REF! | Y5: =IFERROR(__xludf.DUMMYFUNCTION("IF(query(Data!A:M,CONCATENATE(""select Col13 where Col1 = '"",C5,""' and Col8 = 'Labour Protection and Right to Work'""),0)>70,1,0)"),"#REF!") -> #REF! | Z5: =IFERROR(__xludf.DUMMYFUNCTION("IF(query(Data!A:M,CONCATENATE(""select Col13 where Col1 = '"",C5,""' and Col8 = 'Safety, Accuracy and Reliability'""),0)>70,1,0)"),"#REF!") -> #REF! | AA5: =IFERROR(__xludf.DUMMYFUNCTION("IF(query(Data!A:M,CONCATENATE(""select Col13 where Col1 = '"",C5,""' and Col8 = 'Transparency and Explainability'""),0)>70,1,0)"),"#REF!") -> #REF! | AB5: =COUNTIFS(Data!AF:AF,"1",Data!A:A,C5) -> 0 | AC5: =COUNTIFS(Data!X:X,">0",Data!A:A,C5) -> 0 | AD5: =COUNTIFS(Data!AJ:AJ,"12",Data!A:A,C5) -> 0 | AE5: =COUNTIFS(Data!AJ:AJ,"17",Data!A:A,C5) -> 0 | AF5: =COUNTIFS(Data!Y:Y,">0",Data!A:A,C5) -> 0 | AG5: =IF(COUNTIFS(Data!AO:AO,"1",Data!A:A,C5)>0,"Sí","No") -> No | AH5: =IFERROR(__xludf.DUMMYFUNCTION("IFERROR(query(query(Data!A:BS,CONCATENATE(""select Col50, count(Col49) where Col1 = '"",C5,""' group by Col50"")), CONCATENATE(""select Col1 where Col2 = "",query(query(query(Data!A:BS,CONCATENATE(""select Col50, count(Col49) where Col1 = '"",C5,""' and C"&"ol50 <> 'Other' and Col50 is not null group by Col50"")),""select max(Col2)"",0),""Select *"",0),"" limit 1""),0))"),"") | AI5: =IFERROR(VLOOKUP(AH5,ref!$A:$B,2,FALSE),"") | AJ5: =IF(COUNTIFS(Data!BI:BI,"1",Data!A:A,C5)>0,"Sí","No") -> No | AK5: =IFERROR(__xludf.DUMMYFUNCTION("IFERROR(query(query(Data!A:BS,CONCATENATE(""select Col70, count(Col69) where Col1 = '"",C5,""' group by Col70"")), CONCATENATE(""select Col1 where Col2 = "",query(query(query(Data!A:BS,CONCATENATE(""select Col70, count(Col69) where Col1 = '"",C5,""' and C"&"ol70 <> 'Other' and Col70 is not null group by Col70"")),""select max(Col2)"",0),""Select *"",0),"" limit 1""),0))"),"") | AL5: =IFERROR(VLOOKUP(AK5,ref!$A:$B,2,FALSE),"")
A6: 91 | B6: ATG | C6: Antigua and Barbuda | D6: Antigua y Barbuda | E6: Caribe | F6: América | G6: América Latina y el Caribe | H6: 4.7158949 | I6: 0 | J6: 9.3843097 | K6: 4.8108553 | L6: 6.0078571 | M6: 2.6415556 | N6: 7.9246667 | O6: Alto | P6: Alto | Q6: Muy alto | R6: =XLOOKUP(max(L6:N6),L6:N6,$L$2:$N$2,"",0) -> cap | S6: =IFERROR(__xludf.DUMMYFUNCTION("IF(query(Data!A:M,CONCATENATE(""select Col13 where Col1 = '"",C6,""' and Col8 = 'Bias and Unfair Discrimination'""),0)>70,1,0)"),"#REF!") -> #REF! | T6: =IFERROR(__xludf.DUMMYFUNCTION("IF(query(Data!A:M,CONCATENATE(""select Col13 where Col1 = '"",C6,""' and Col8 = 'Childrens Rights'""),0)>70,1,0)"),"#REF!") -> #REF! | U6: =IFERROR(__xludf.DUMMYFUNCTION("IF(query(Data!A:M,CONCATENATE(""select Col13 where Col1 = '"",C6,""' and Col8 = 'Cultural and Linguistic Diversity'""),0)>70,1,0)"),"#REF!") -> #REF! | V6: =IFERROR(__xludf.DUMMYFUNCTION("IF(query(Data!A:M,CONCATENATE(""select Col13 where Col1 = '"",C6,""' and Col8 = 'Data Protection and Privacy'""),0)>70,1,0)"),"#REF!") -> #REF! | W6: =IFERROR(__xludf.DUMMYFUNCTION("IF(query(Data!A:M,CONCATENATE(""select Col13 where Col1 = '"",C6,""' and Col8 = 'Gender Equality'""),0)>70,1,0)"),"#REF!") -> #REF! | X6: =IFERROR(__xludf.DUMMYFUNCTION("IF(query(Data!A:M,CONCATENATE(""select Col13 where Col1 = '"",C6,""' and Col8 = 'Human Oversight and Determination'""),0)>70,1,0)"),"#REF!") -> #REF! | Y6: =IFERROR(__xludf.DUMMYFUNCTION("IF(query(Data!A:M,CONCATENATE(""select Col13 where Col1 = '"",C6,""' and Col8 = 'Labour Protection and Right to Work'""),0)>70,1,0)"),"#REF!") -> #REF! | Z6: =IFERROR(__xludf.DUMMYFUNCTION("IF(query(Data!A:M,CONCATENATE(""select Col13 where Col1 = '"",C6,""' and Col8 = 'Safety, Accuracy and Reliability'""),0)>70,1,0)"),"#REF!") -> #REF! | AA6: =IFERROR(__xludf.DUMMYFUNCTION("IF(query(Data!A:M,CONCATENATE(""select Col13 where Col1 = '"",C6,""' and Col8 = 'Transparency and Explainability'""),0)>70,1,0)"),"#REF!") -> #REF! | AB6: =COUNTIFS(Data!AF:AF,"1",Data!A:A,C6) -> 0 | AC6: =COUNTIFS(Data!X:X,">0",Data!A:A,C6) -> 0 | AD6: =COUNTIFS(Data!AJ:AJ,"12",Data!A:A,C6) -> 0 | AE6: =COUNTIFS(Data!AJ:AJ,"17",Data!A:A,C6) -> 0 | AF6: =COUNTIFS(Data!Y:Y,">0",Data!A:A,C6) -> 0 | AG6: =IF(COUNTIFS(Data!AO:AO,"1",Data!A:A,C6)>0,"Sí","No") -> No | AH6: =IFERROR(__xludf.DUMMYFUNCTION("IFERROR(query(query(Data!A:BS,CONCATENATE(""select Col50, count(Col49) where Col1 = '"",C6,""' group by Col50"")), CONCATENATE(""select Col1 where Col2 = "",query(query(query(Data!A:BS,CONCATENATE(""select Col50, count(Col49) where Col1 = '"",C6,""' and C"&"ol50 <> 'Other' and Col50 is not null group by Col50"")),""select max(Col2)"",0),""Select *"",0),"" limit 1""),0))"),"") | AI6: =IFERROR(VLOOKUP(AH6,ref!$A:$B,2,FALSE),"") | AJ6: =IF(COUNTIFS(Data!BI:BI,"1",Data!A:A,C6)>0,"Sí","No") -> No | AK6: =IFERROR(__xludf.DUMMYFUNCTION("IFERROR(query(query(Data!A:BS,CONCATENATE(""select Col70, count(Col69) where Col1 = '"",C6,""' group by Col70"")), CONCATENATE(""select Col1 where Col2 = "",query(query(query(Data!A:BS,CONCATENATE(""select Col70, count(Col69) where Col1 = '"",C6,""' and C"&"ol70 <> 'Other' and Col70 is not null group by Col70"")),""select max(Col2)"",0),""Select *"",0),"" limit 1""),0))"),"") | AL6: =IFERROR(VLOOKUP(AK6,ref!$A:$B,2,FALSE),"")
A7: 40 | B7: SAU | C7: Saudi Arabia | D7: Arabia Saudita | E7: Medio Oriente | F7: Asia | G7: Asia Occidental | H7: 28.947099 | I7: 25.595312 | J7: 42.866186 | K7: 7.8125 | L7: 26.276714 | M7: 27.685444 | N7: 38.962667 | O7: Alto | P7: Alto | Q7: Muy bajo | R7: =XLOOKUP(max(L7:N7),L7:N7,$L$2:$N$2,"",0) -> cap | S7: =IFERROR(__xludf.DUMMYFUNCTION("IF(query(Data!A:M,CONCATENATE(""select Col13 where Col1 = '"",C7,""' and Col8 = 'Bias and Unfair Discrimination'""),0)>70,1,0)"),"#REF!") -> #REF! | T7: =IFERROR(__xludf.DUMMYFUNCTION("IF(query(Data!A:M,CONCATENATE(""select Col13 where Col1 = '"",C7,""' and Col8 = 'Childrens Rights'""),0)>70,1,0)"),"#REF!") -> #REF! | U7: =IFERROR(__xludf.DUMMYFUNCTION("IF(query(Data!A:M,CONCATENATE(""select Col13 where Col1 = '"",C7,""' and Col8 = 'Cultural and Linguistic Diversity'""),0)>70,1,0)"),"#REF!") -> #REF! | V7: =IFERROR(__xludf.DUMMYFUNCTION("IF(query(Data!A:M,CONCATENATE(""select Col13 where Col1 = '"",C7,""' and Col8 = 'Data Protection and Privacy'""),0)>70,1,0)"),"#REF!") -> #REF! | W7: =IFERROR(__xludf.DUMMYFUNCTION("IF(query(Data!A:M,CONCATENATE(""select Col13 where Col1 = '"",C7,""' and Col8 = 'Gender Equality'""),0)>70,1,0)"),"#REF!") -> #REF! | X7: =IFERROR(__xludf.DUMMYFUNCTION("IF(query(Data!A:M,CONCATENATE(""select Col13 where Col1 = '"",C7,""' and Col8 = 'Human Oversight and Determination'""),0)>70,1,0)"),"#REF!") -> #REF! | Y7: =IFERROR(__xludf.DUMMYFUNCTION("IF(query(Data!A:M,CONCATENATE(""select Col13 where Col1 = '"",C7,""' and Col8 = 'Labour Protection and Right to Work'""),0)>70,1,0)"),"#REF!") -> #REF! | Z7: =IFERROR(__xludf.DUMMYFUNCTION("IF(query(Data!A:M,CONCATENATE(""select Col13 where Col1 = '"",C7,""' and Col8 = 'Safety, Accuracy and Reliability'""),0)>70,1,0)"),"#REF!") -> #REF! | AA7: =IFERROR(__xludf.DUMMYFUNCTION("IF(query(Data!A:M,CONCATENATE(""select Col13 where Col1 = '"",C7,""' and Col8 = 'Transparency and Explainability'""),0)>70,1,0)"),"#REF!") -> #REF! | AB7: =COUNTIFS(Data!AF:AF,"1",Data!A:A,C7) -> 0 | AC7: =COUNTIFS(Data!X:X,">0",Data!A:A,C7) -> 0 | AD7: =COUNTIFS(Data!AJ:AJ,"12",Data!A:A,C7) -> 0 | AE7: =COUNTIFS(Data!AJ:AJ,"17",Data!A:A,C7) -> 0 | AF7: =COUNTIFS(Data!Y:Y,">0",Data!A:A,C7) -> 0 | AG7: =IF(COUNTIFS(Data!AO:AO,"1",Data!A:A,C7)>0,"Sí","No") -> No | AH7: =IFERROR(__xludf.DUMMYFUNCTION("IFERROR(query(query(Data!A:BS,CONCATENATE(""select Col50, count(Col49) where Col1 = '"",C7,""' group by Col50"")), CONCATENATE(""select Col1 where Col2 = "",query(query(query(Data!A:BS,CONCATENATE(""select Col50, count(Col49) where Col1 = '"",C7,""' and C"&"ol50 <> 'Other' and Col50 is not null group by Col50"")),""select max(Col2)"",0),""Select *"",0),"" limit 1""),0))"),"") | AI7: =IFERROR(VLOOKUP(AH7,ref!$A:$B,2,FALSE),"") | AJ7: =IF(COUNTIFS(Data!BI:BI,"1",Data!A:A,C7)>0,"Sí","No") -> No | AK7: =IFERROR(__xludf.DUMMYFUNCTION("IFERROR(query(query(Data!A:BS,CONCATENATE(""select Col70, count(Col69) where Col1 = '"",C7,""' group by Col70"")), CONCATENATE(""select Col1 where Col2 = "",query(query(query(Data!A:BS,CONCATENATE(""select Col70, count(Col69) where Col1 = '"",C7,""' and C"&"ol70 <> 'Other' and Col70 is not null group by Col70"")),""select max(Col2)"",0),""Select *"",0),"" limit 1""),0))"),"") | AL7: =IFERROR(VLOOKUP(AK7,ref!$A:$B,2,FALSE),"")
A8: 104 | B8: DZA | C8: Algeria | D8: Argelia | E8: África | F8: África | G8: África del Norte | H8: 2.6618462 | I8: 0 | J8: 4.5301638 | K8: 4.2489035 | L8: 0 | M8: 1.0763333 | N8: 13.629333 | O8: Muy bajo | P8: Bajo | Q8: Bajo | R8: =XLOOKUP(max(L8:N8),L8:N8,$L$2:$N$2,"",0) -> cap | S8: =IFERROR(__xludf.DUMMYFUNCTION("IF(query(Data!A:M,CONCATENATE(""select Col13 where Col1 = '"",C8,""' and Col8 = 'Bias and Unfair Discrimination'""),0)>70,1,0)"),"#REF!") -> #REF! | T8: =IFERROR(__xludf.DUMMYFUNCTION("IF(query(Data!A:M,CONCATENATE(""select Col13 where Col1 = '"",C8,""' and Col8 = 'Childrens Rights'""),0)>70,1,0)"),"#REF!") -> #REF! | U8: =IFERROR(__xludf.DUMMYFUNCTION("IF(query(Data!A:M,CONCATENATE(""select Col13 where Col1 = '"",C8,""' and Col8 = 'Cultural and Linguistic Diversity'""),0)>70,1,0)"),"#REF!") -> #REF! | V8: =IFERROR(__xludf.DUMMYFUNCTION("IF(query(Data!A:M,CONCATENATE(""select Col13 where Col1 = '"",C8,""' and Col8 = 'Data Protection and Privacy'""),0)>70,1,0)"),"#REF!") -> #REF! | W8: =IFERROR(__xludf.DUMMYFUNCTION("IF(query(Data!A:M,CONCATENATE(""select Col13 where Col1 = '"",C8,""' and Col8 = 'Gender Equality'""),0)>70,1,0)"),"#REF!") -> #REF! | X8: =IFERROR(__xludf.DUMMYFUNCTION("IF(query(Data!A:M,CONCATENATE(""select Col13 where Col1 = '"",C8,""' and Col8 = 'Human Oversight and Determination'""),0)>70,1,0)"),"#REF!") -> #REF! | Y8: =IFERROR(__xludf.DUMMYFUNCTION("IF(query(Data!A:M,CONCATENATE(""select Col13 where Col1 = '"",C8,""' and Col8 = 'Labour Protection and Right to Work'""),0)>70,1,0)"),"#REF!") -> #REF! | Z8: =IFERROR(__xludf.DUMMYFUNCTION("IF(query(Data!A:M,CONCATENATE(""select Col13 where Col1 = '"",C8,""' and Col8 = 'Safety, Accuracy and Reliability'""),0)>70,1,0)"),"#REF!") -> #REF! | AA8: =IFERROR(__xludf.DUMMYFUNCTION("IF(query(Data!A:M,CONCATENATE(""select Col13 where Col1 = '"",C8,""' and Col8 = 'Transparency and Explainability'""),0)>70,1,0)"),"#REF!") -> #REF! | AB8: =COUNTIFS(Data!AF:AF,"1",Data!A:A,C8) -> 0 | AC8: =COUNTIFS(Data!X:X,">0",Data!A:A,C8) -> 0 | AD8: =COUNTIFS(Data!AJ:AJ,"12",Data!A:A,C8) -> 0 | AE8: =COUNTIFS(Data!AJ:AJ,"17",Data!A:A,C8) -> 0 | AF8: =COUNTIFS(Data!Y:Y,">0",Data!A:A,C8) -> 0 | AG8: =IF(COUNTIFS(Data!AO:AO,"1",Data!A:A,C8)>0,"Sí","No") -> No | AH8: =IFERROR(__xludf.DUMMYFUNCTION("IFERROR(query(query(Data!A:BS,CONCATENATE(""select Col50, count(Col49) where Col1 = '"",C8,""' group by Col50"")), CONCATENATE(""select Col1 where Col2 = "",query(query(query(Data!A:BS,CONCATENATE(""select Col50, count(Col49) where Col1 = '"",C8,""' and C"&"ol50 <> 'Other' and Col50 is not null group by Col50"")),""select max(Col2)"",0),""Select *"",0),"" limit 1""),0))"),"") | AI8: =IFERROR(VLOOKUP(AH8,ref!$A:$B,2,FALSE),"") | AJ8: =IF(COUNTIFS(Data!BI:BI,"1",Data!A:A,C8)>0,"Sí","No") -> No | AK8: =IFERROR(__xludf.DUMMYFUNCTION("IFERROR(query(query(Data!A:BS,CONCATENATE(""select Col70, count(Col69) where Col1 = '"",C8,""' group by Col70"")), CONCATENATE(""select Col1 where Col2 = "",query(query(query(Data!A:BS,CONCATENATE(""select Col70, count(Col69) where Col1 = '"",C8,""' and C"&"ol70 <> 'Other' and Col70 is not null group by Col70"")),""select max(Col2)"",0),""Select *"",0),"" limit 1""),0))"),"") | AL8: =IFERROR(VLOOKUP(AK8,ref!$A:$B,2,FALSE),"")
A9: 54 | B9: ARG | C9: Argentina | D9: Argentina | E9: América del Sur y Central | F9: América | G9: América Latina y el Caribe | H9: 21.953223 | I9: 10.48649 | J9: 29.470581 | K9: 29.851974 | L9: 25.725 | M9: 18.413333 | N9: 23.772333 | O9: Bajo | P9: Medio | Q9: Muy alto | R9: =XLOOKUP(max(L9:N9),L9:N9,$L$2:$N$2,"",0) -> ddhh | S9: =IFERROR(__xludf.DUMMYFUNCTION("IF(query(Data!A:M,CONCATENATE(""select Col13 where Col1 = '"",C9,""' and Col8 = 'Bias and Unfair Discrimination'""),0)>70,1,0)"),"#REF!") -> #REF! | T9: =IFERROR(__xludf.DUMMYFUNCTION("IF(query(Data!A:M,CONCATENATE(""select Col13 where Col1 = '"",C9,""' and Col8 = 'Childrens Rights'""),0)>70,1,0)"),"#REF!") -> #REF! | U9: =IFERROR(__xludf.DUMMYFUNCTION("IF(query(Data!A:M,CONCATENATE(""select Col13 where Col1 = '"",C9,""' and Col8 = 'Cultural and Linguistic Diversity'""),0)>70,1,0)"),"#REF!") -> #REF! | V9: =IFERROR(__xludf.DUMMYFUNCTION("IF(query(Data!A:M,CONCATENATE(""select Col13 where Col1 = '"",C9,""' and Col8 = 'Data Protection and Privacy'""),0)>70,1,0)"),"#REF!") -> #REF! | W9: =IFERROR(__xludf.DUMMYFUNCTION("IF(query(Data!A:M,CONCATENATE(""select Col13 where Col1 = '"",C9,""' and Col8 = 'Gender Equality'""),0)>70,1,0)"),"#REF!") -> #REF! | X9: =IFERROR(__xludf.DUMMYFUNCTION("IF(query(Data!A:M,CONCATENATE(""select Col13 where Col1 = '"",C9,""' and Col8 = 'Human Oversight and Determination'""),0)>70,1,0)"),"#REF!") -> #REF! | Y9: =IFERROR(__xludf.DUMMYFUNCTION("IF(query(Data!A:M,CONCATENATE(""select Col13 where Col1 = '"",C9,""' and Col8 = 'Labour Protection and Right to Work'""),0)>70,1,0)"),"#REF!") -> #REF! | Z9: =IFERROR(__xludf.DUMMYFUNCTION("IF(query(Data!A:M,CONCATENATE(""select Col13 where Col1 = '"",C9,""' and Col8 = 'Safety, Accuracy and Reliability'""),0)>70,1,0)"),"#REF!") -> #REF! | AA9: =IFERROR(__xludf.DUMMYFUNCTION("IF(query(Data!A:M,CONCATENATE(""select Col13 where Col1 = '"",C9,""' and Col8 = 'Transparency and Explainability'""),0)>70,1,0)"),"#REF!") -> #REF! | AB9: =COUNTIFS(Data!AF:AF,"1",Data!A:A,C9) -> 0 | AC9: =COUNTIFS(Data!X:X,">0",Data!A:A,C9) -> 0 | AD9: =COUNTIFS(Data!AJ:AJ,"12",Data!A:A,C9) -> 0 | AE9: =COUNTIFS(Data!AJ:AJ,"17",Data!A:A,C9) -> 0 | AF9: =COUNTIFS(Data!Y:Y,">0",Data!A:A,C9) -> 0 | AG9: =IF(COUNTIFS(Data!AO:AO,"1",Data!A:A,C9)>0,"Sí","No") -> No | AH9: =IFERROR(__xludf.DUMMYFUNCTION("IFERROR(query(query(Data!A:BS,CONCATENATE(""select Col50, count(Col49) where Col1 = '"",C9,""' group by Col50"")), CONCATENATE(""select Col1 where Col2 = "",query(query(query(Data!A:BS,CONCATENATE(""select Col50, count(Col49) where Col1 = '"",C9,""' and C"&"ol50 <> 'Other' and Col50 is not null group by Col50"")),""select max(Col2)"",0),""Select *"",0),"" limit 1""),0))"),"") | AI9: =IFERROR(VLOOKUP(AH9,ref!$A:$B,2,FALSE),"") | AJ9: =IF(COUNTIFS(Data!BI:BI,"1",Data!A:A,C9)>0,"Sí","No") -> No | AK9: =IFERROR(__xludf.DUMMYFUNCTION("IFERROR(query(query(Data!A:BS,CONCATENATE(""select Col70, count(Col69) where Col1 = '"",C9,""' group by Col70"")), CONCATENATE(""select Col1 where Col2 = "",query(query(query(Data!A:BS,CONCATENATE(""select Col70, count(Col69) where Col1 = '"",C9,""' and C"&"ol70 <> 'Other' and Col70 is not null group by Col70"")),""select max(Col2)"",0),""Select *"",0),"" limit 1""),0))"),"") | AL9: =IFERROR(VLOOKUP(AK9,ref!$A:$B,2,FALSE),"")
A10: 101 | B10: ARM | C10: Armenia | D10: Armenia | E10: Asia y Oceanía | F10: Asia | G10: Asia Occidental | H10: 3.2991973 | I10: 0 | J10: 5.7534757 | K10: 4.9890351 | L10: 3.8004286 | M10: 1.58 | N10: 7.2876667 | O10: Alto | P10: Alto | Q10: Alto | R10: =XLOOKUP(max(L10:N10),L10:N10,$L$2:$N$2,"",0) -> cap | S10: =IFERROR(__xludf.DUMMYFUNCTION("IF(query(Data!A:M,CONCATENATE(""select Col13 where Col1 = '"",C10,""' and Col8 = 'Bias and Unfair Discrimination'""),0)>70,1,0)"),"#REF!") -> #REF! | T10: =IFERROR(__xludf.DUMMYFUNCTION("IF(query(Data!A:M,CONCATENATE(""select Col13 where Col1 = '"",C10,""' and Col8 = 'Childrens Rights'""),0)>70,1,0)"),"#REF!") -> #REF! | U10: =IFERROR(__xludf.DUMMYFUNCTION("IF(query(Data!A:M,CONCATENATE(""select Col13 where Col1 = '"",C10,""' and Col8 = 'Cultural and Linguistic Diversity'""),0)>70,1,0)"),"#REF!") -> #REF! | V10: =IFERROR(__xludf.DUMMYFUNCTION("IF(query(Data!A:M,CONCATENATE(""select Col13 where Col1 = '"",C10,""' and Col8 = 'Data Protection and Privacy'""),0)>70,1,0)"),"#REF!") -> #REF! | W10: =IFERROR(__xludf.DUMMYFUNCTION("IF(query(Data!A:M,CONCATENATE(""select Col13 where Col1 = '"",C10,""' and Col8 = 'Gender Equality'""),0)>70,1,0)"),"#REF!") -> #REF! | X10: =IFERROR(__xludf.DUMMYFUNCTION("IF(query(Data!A:M,CONCATENATE(""select Col13 where Col1 = '"",C10,""' and Col8 = 'Human Oversight and Determination'""),0)>70,1,0)"),"#REF!") -> #REF! | Y10: =IFERROR(__xludf.DUMMYFUNCTION("IF(query(Data!A:M,CONCATENATE(""select Col13 where Col1 = '"",C10,""' and Col8 = 'Labour Protection and Right to Work'""),0)>70,1,0)"),"#REF!") -> #REF! | Z10: =IFERROR(__xludf.DUMMYFUNCTION("IF(query(Data!A:M,CONCATENATE(""select Col13 where Col1 = '"",C10,""' and Col8 = 'Safety, Accuracy and Reliability'""),0)>70,1,0)"),"#REF!") -> #REF! | AA10: =IFERROR(__xludf.DUMMYFUNCTION("IF(query(Data!A:M,CONCATENATE(""select Col13 where Col1 = '"",C10,""' and Col8 = 'Transparency and Explainability'""),0)>70,1,0)"),"#REF!") -> #REF! | AB10: =COUNTIFS(Data!AF:AF,"1",Data!A:A,C10) -> 0 | AC10: =COUNTIFS(Data!X:X,">0",Data!A:A,C10) -> 0 | AD10: =COUNTIFS(Data!AJ:AJ,"12",Data!A:A,C10) -> 0 | AE10: =COUNTIFS(Data!AJ:AJ,"17",Data!A:A,C10) -> 0 | AF10: =COUNTIFS(Data!Y:Y,">0",Data!A:A,C10) -> 0 | AG10: =IF(COUNTIFS(Data!AO:AO,"1",Data!A:A,C10)>0,"Sí","No") -> No | AH10: =IFERROR(__xludf.DUMMYFUNCTION("IFERROR(query(query(Data!A:BS,CONCATENATE(""select Col50, count(Col49) where Col1 = '"",C10,""' group by Col50"")), CONCATENATE(""select Col1 where Col2 = "",query(query(query(Data!A:BS,CONCATENATE(""select Col50, count(Col49) where Col1 = '"",C10,""' and"&" Col50 <> 'Other' and Col50 is not null group by Col50"")),""select max(Col2)"",0),""Select *"",0),"" limit 1""),0))"),"") | AI10: =IFERROR(VLOOKUP(AH10,ref!$A:$B,2,FALSE),"") | AJ10: =IF(COUNTIFS(Data!BI:BI,"1",Data!A:A,C10)>0,"Sí","No") -> No | AK10: =IFERROR(__xludf.DUMMYFUNCTION("IFERROR(query(query(Data!A:BS,CONCATENATE(""select Col70, count(Col69) where Col1 = '"",C10,""' group by Col70"")), CONCATENATE(""select Col1 where Col2 = "",query(query(query(Data!A:BS,CONCATENATE(""select Col70, count(Col69) where Col1 = '"",C10,""' and"&" Col70 <> 'Other' and Col70 is not null group by Col70"")),""select max(Col2)"",0),""Select *"",0),"" limit 1""),0))"),"") | AL10: =IFERROR(VLOOKUP(AK10,ref!$A:$B,2,FALSE),"")
A11: 10 | B11: AUS | C11: Australia | D11: Australia | E11: Asia y Oceanía | F11: Oceanía | G11: Australia y Nueva Zelanda | H11: 56.215689 | I11: 34.692569 | J11: 72.437935 | K11: 66.817434 | L11: 71.312286 | M11: 52.672667 | N11: 31.619 | O11: Muy alto | P11: Muy alto | Q11: Muy alto | R11: =XLOOKUP(max(L11:N11),L11:N11,$L$2:$N$2,"",0) -> ddhh | S11: =IFERROR(__xludf.DUMMYFUNCTION("IF(query(Data!A:M,CONCATENATE(""select Col13 where Col1 = '"",C11,""' and Col8 = 'Bias and Unfair Discrimination'""),0)>70,1,0)"),"#REF!") -> #REF! | T11: =IFERROR(__xludf.DUMMYFUNCTION("IF(query(Data!A:M,CONCATENATE(""select Col13 where Col1 = '"",C11,""' and Col8 = 'Childrens Rights'""),0)>70,1,0)"),"#REF!") -> #REF! | U11: =IFERROR(__xludf.DUMMYFUNCTION("IF(query(Data!A:M,CONCATENATE(""select Col13 where Col1 = '"",C11,""' and Col8 = 'Cultural and Linguistic Diversity'""),0)>70,1,0)"),"#REF!") -> #REF! | V11: =IFERROR(__xludf.DUMMYFUNCTION("IF(query(Data!A:M,CONCATENATE(""select Col13 where Col1 = '"",C11,""' and Col8 = 'Data Protection and Privacy'""),0)>70,1,0)"),"#REF!") -> #REF! | W11: =IFERROR(__xludf.DUMMYFUNCTION("IF(query(Data!A:M,CONCATENATE(""select Col13 where Col1 = '"",C11,""' and Col8 = 'Gender Equality'""),0)>70,1,0)"),"#REF!") -> #REF! | X11: =IFERROR(__xludf.DUMMYFUNCTION("IF(query(Data!A:M,CONCATENATE(""select Col13 where Col1 = '"",C11,""' and Col8 = 'Human Oversight and Determination'""),0)>70,1,0)"),"#REF!") -> #REF! | Y11: =IFERROR(__xludf.DUMMYFUNCTION("IF(query(Data!A:M,CONCATENATE(""select Col13 where Col1 = '"",C11,""' and Col8 = 'Labour Protection and Right to Work'""),0)>70,1,0)"),"#REF!") -> #REF! | Z11: =IFERROR(__xludf.DUMMYFUNCTION("IF(query(Data!A:M,CONCATENATE(""select Col13 where Col1 = '"",C11,""' and Col8 = 'Safety, Accuracy and Reliability'""),0)>70,1,0)"),"#REF!") -> #REF! | AA11: =IFERROR(__xludf.DUMMYFUNCTION("IF(query(Data!A:M,CONCATENATE(""select Col13 where Col1 = '"",C11,""' and Col8 = 'Transparency and Explainability'""),0)>70,1,0)"),"#REF!") -> #REF! | AB11: =COUNTIFS(Data!AF:AF,"1",Data!A:A,C11) -> 0 | AC11: =COUNTIFS(Data!X:X,">0",Data!A:A,C11) -> 0 | AD11: =COUNTIFS(Data!AJ:AJ,"12",Data!A:A,C11) -> 0 | AE11: =COUNTIFS(Data!AJ:AJ,"17",Data!A:A,C11) -> 0 | AF11: =COUNTIFS(Data!Y:Y,">0",Data!A:A,C11) -> 0 | AG11: =IF(COUNTIFS(Data!AO:AO,"1",Data!A:A,C11)>0,"Sí","No") -> No | AH11: =IFERROR(__xludf.DUMMYFUNCTION("IFERROR(query(query(Data!A:BS,CONCATENATE(""select Col50, count(Col49) where Col1 = '"",C11,""' group by Col50"")), CONCATENATE(""select Col1 where Col2 = "",query(query(query(Data!A:BS,CONCATENATE(""select Col50, count(Col49) where Col1 = '"",C11,""' and"&" Col50 <> 'Other' and Col50 is not null group by Col50"")),""select max(Col2)"",0),""Select *"",0),"" limit 1""),0))"),"") | AI11: =IFERROR(VLOOKUP(AH11,ref!$A:$B,2,FALSE),"") | AJ11: =IF(COUNTIFS(Data!BI:BI,"1",Data!A:A,C11)>0,"Sí","No") -> No | AK11: =IFERROR(__xludf.DUMMYFUNCTION("IFERROR(query(query(Data!A:BS,CONCATENATE(""select Col70, count(Col69) where Col1 = '"",C11,""' group by Col70"")), CONCATENATE(""select Col1 where Col2 = "",query(query(query(Data!A:BS,CONCATENATE(""select Col70, count(Col69) where Col1 = '"",C11,""' and"&" Col70 <> 'Other' and Col70 is not null group by Col70"")),""select max(Col2)"",0),""Select *"",0),"" limit 1""),0))"),"") | AL11: =IFERROR(VLOOKUP(AK11,ref!$A:$B,2,FALSE),"")
A12: 30 | B12: AUT | C12: Austria | D12: Austria | E12: Europa | F12: Europa | G12: Europa Occidental | H12: 35.762496 | I12: 55.850712 | J12: 26.866932 | K12: 13.377193 | L12: 28.639429 | M12: 37.012333 | N12: 48.633667 | O12: Muy alto | P12: Muy alto | Q12: Muy alto | R12: =XLOOKUP(max(L12:N12),L12:N12,$L$2:$N$2,"",0) -> cap | S12: =IFERROR(__xludf.DUMMYFUNCTION("IF(query(Data!A:M,CONCATENATE(""select Col13 where Col1 = '"",C12,""' and Col8 = 'Bias and Unfair Discrimination'""),0)>70,1,0)"),"#REF!") -> #REF! | T12: =IFERROR(__xludf.DUMMYFUNCTION("IF(query(Data!A:M,CONCATENATE(""select Col13 where Col1 = '"",C12,""' and Col8 = 'Childrens Rights'""),0)>70,1,0)"),"#REF!") -> #REF! | U12: =IFERROR(__xludf.DUMMYFUNCTION("IF(query(Data!A:M,CONCATENATE(""select Col13 where Col1 = '"",C12,""' and Col8 = 'Cultural and Linguistic Diversity'""),0)>70,1,0)"),"#REF!") -> #REF! | V12: =IFERROR(__xludf.DUMMYFUNCTION("IF(query(Data!A:M,CONCATENATE(""select Col13 where Col1 = '"",C12,""' and Col8 = 'Data Protection and Privacy'""),0)>70,1,0)"),"#REF!") -> #REF! | W12: =IFERROR(__xludf.DUMMYFUNCTION("IF(query(Data!A:M,CONCATENATE(""select Col13 where Col1 = '"",C12,""' and Col8 = 'Gender Equality'""),0)>70,1,0)"),"#REF!") -> #REF! | X12: =IFERROR(__xludf.DUMMYFUNCTION("IF(query(Data!A:M,CONCATENATE(""select Col13 where Col1 = '"",C12,""' and Col8 = 'Human Oversight and Determination'""),0)>70,1,0)"),"#REF!") -> #REF! | Y12: =IFERROR(__xludf.DUMMYFUNCTION("IF(query(Data!A:M,CONCATENATE(""select Col13 where Col1 = '"",C12,""' and Col8 = 'Labour Protection and Right to Work'""),0)>70,1,0)"),"#REF!") -> #REF! | Z12: =IFERROR(__xludf.DUMMYFUNCTION("IF(query(Data!A:M,CONCATENATE(""select Col13 where Col1 = '"",C12,""' and Col8 = 'Safety, Accuracy and Reliability'""),0)>70,1,0)"),"#REF!") -> #REF! | AA12: =IFERROR(__xludf.DUMMYFUNCTION("IF(query(Data!A:M,CONCATENATE(""select Col13 where Col1 = '"",C12,""' and Col8 = 'Transparency and Explainability'""),0)>70,1,0)"),"#REF!") -> #REF! | AB12: =COUNTIFS(Data!AF:AF,"1",Data!A:A,C12) -> 0 | AC12: =COUNTIFS(Data!X:X,">0",Data!A:A,C12) -> 0 | AD12: =COUNTIFS(Data!AJ:AJ,"12",Data!A:A,C12) -> 0 | AE12: =COUNTIFS(Data!AJ:AJ,"17",Data!A:A,C12) -> 0 | AF12: =COUNTIFS(Data!Y:Y,">0",Data!A:A,C12) -> 0 | AG12: =IF(COUNTIFS(Data!AO:AO,"1",Data!A:A,C12)>0,"Sí","No") -> No | AH12: =IFERROR(__xludf.DUMMYFUNCTION("IFERROR(query(query(Data!A:BS,CONCATENATE(""select Col50, count(Col49) where Col1 = '"",C12,""' group by Col50"")), CONCATENATE(""select Col1 where Col2 = "",query(query(query(Data!A:BS,CONCATENATE(""select Col50, count(Col49) where Col1 = '"",C12,""' and"&" Col50 <> 'Other' and Col50 is not null group by Col50"")),""select max(Col2)"",0),""Select *"",0),"" limit 1""),0))"),"") | AI12: =IFERROR(VLOOKUP(AH12,ref!$A:$B,2,FALSE),"") | AJ12: =IF(COUNTIFS(Data!BI:BI,"1",Data!A:A,C12)>0,"Sí","No") -> No | AK12: =IFERROR(__xludf.DUMMYFUNCTION("IFERROR(query(query(Data!A:BS,CONCATENATE(""select Col70, count(Col69) where Col1 = '"",C12,""' group by Col70"")), CONCATENATE(""select Col1 where Col2 = "",query(query(query(Data!A:BS,CONCATENATE(""select Col70, count(Col69) where Col1 = '"",C12,""' and"&" Col70 <> 'Other' and Col70 is not null group by Col70"")),""select max(Col2)"",0),""Select *"",0),"" limit 1""),0))"),"") | AL12: =IFERROR(VLOOKUP(AK12,ref!$A:$B,2,FALSE),"")
A13: 88 | B13: AZE | C13: Azerbaijan | D13: Azerbaiyán | E13: Asia y Oceanía | F13: Asia | G13: Asia Occidental | H13: 5.8644282 | I13: 3.703244 | J13: 10.09434 | K13: 1.7269737 | L13: 2.9081429 | M13: 5.2868889 | N13: 14.495 | O13: Medio | P13: Medio | Q13: Muy bajo | R13: =XLOOKUP(max(L13:N13),L13:N13,$L$2:$N$2,"",0) -> cap | S13: =IFERROR(__xludf.DUMMYFUNCTION("IF(query(Data!A:M,CONCATENATE(""select Col13 where Col1 = '"",C13,""' and Col8 = 'Bias and Unfair Discrimination'""),0)>70,1,0)"),"#REF!") -> #REF! | T13: =IFERROR(__xludf.DUMMYFUNCTION("IF(query(Data!A:M,CONCATENATE(""select Col13 where Col1 = '"",C13,""' and Col8 = 'Childrens Rights'""),0)>70,1,0)"),"#REF!") -> #REF! | U13: =IFERROR(__xludf.DUMMYFUNCTION("IF(query(Data!A:M,CONCATENATE(""select Col13 where Col1 = '"",C13,""' and Col8 = 'Cultural and Linguistic Diversity'""),0)>70,1,0)"),"#REF!") -> #REF! | V13: =IFERROR(__xludf.DUMMYFUNCTION("IF(query(Data!A:M,CONCATENATE(""select Col13 where Col1 = '"",C13,""' and Col8 = 'Data Protection and Privacy'""),0)>70,1,0)"),"#REF!") -> #REF! | W13: =IFERROR(__xludf.DUMMYFUNCTION("IF(query(Data!A:M,CONCATENATE(""select Col13 where Col1 = '"",C13,""' and Col8 = 'Gender Equality'""),0)>70,1,0)"),"#REF!") -> #REF! | X13: =IFERROR(__xludf.DUMMYFUNCTION("IF(query(Data!A:M,CONCATENATE(""select Col13 where Col1 = '"",C13,""' and Col8 = 'Human Oversight and Determination'""),0)>70,1,0)"),"#REF!") -> #REF! | Y13: =IFERROR(__xludf.DUMMYFUNCTION("IF(query(Data!A:M,CONCATENATE(""select Col13 where Col1 = '"",C13,""' and Col8 = 'Labour Protection and Right to Work'""),0)>70,1,0)"),"#REF!") -> #REF! | Z13: =IFERROR(__xludf.DUMMYFUNCTION("IF(query(Data!A:M,CONCATENATE(""select Col13 where Col1 = '"",C13,""' and Col8 = 'Safety, Accuracy and Reliability'""),0)>70,1,0)"),"#REF!") -> #REF! | AA13: =IFERROR(__xludf.DUMMYFUNCTION("IF(query(Data!A:M,CONCATENATE(""select Col13 where Col1 = '"",C13,""' and Col8 = 'Transparency and Explainability'""),0)>70,1,0)"),"#REF!") -> #REF! | AB13: =COUNTIFS(Data!AF:AF,"1",Data!A:A,C13) -> 0 | AC13: =COUNTIFS(Data!X:X,">0",Data!A:A,C13) -> 0 | AD13: =COUNTIFS(Data!AJ:AJ,"12",Data!A:A,C13) -> 0 | AE13: =COUNTIFS(Data!AJ:AJ,"17",Data!A:A,C13) -> 0 | AF13: =COUNTIFS(Data!Y:Y,">0",Data!A:A,C13) -> 0 | AG13: =IF(COUNTIFS(Data!AO:AO,"1",Data!A:A,C13)>0,"Sí","No") -> No | AH13: =IFERROR(__xludf.DUMMYFUNCTION("IFERROR(query(query(Data!A:BS,CONCATENATE(""select Col50, count(Col49) where Col1 = '"",C13,""' group by Col50"")), CONCATENATE(""select Col1 where Col2 = "",query(query(query(Data!A:BS,CONCATENATE(""select Col50, count(Col49) where Col1 = '"",C13,""' and"&" Col50 <> 'Other' and Col50 is not null group by Col50"")),""select max(Col2)"",0),""Select *"",0),"" limit 1""),0))"),"") | AI13: =IFERROR(VLOOKUP(AH13,ref!$A:$B,2,FALSE),"") | AJ13: =IF(COUNTIFS(Data!BI:BI,"1",Data!A:A,C13)>0,"Sí","No") -> No | AK13: =IFERROR(__xludf.DUMMYFUNCTION("IFERROR(query(query(Data!A:BS,CONCATENATE(""select Col70, count(Col69) where Col1 = '"",C13,""' group by Col70"")), CONCATENATE(""select Col1 where Col2 = "",query(query(query(Data!A:BS,CONCATENATE(""select Col70, count(Col69) where Col1 = '"",C13,""' and"&" Col70 <> 'Other' and Col70 is not null group by Col70"")),""select max(Col2)"",0),""Select *"",0),"" limit 1""),0))"),"") | AL13: =IFERROR(VLOOKUP(AK13,ref!$A:$B,2,FALSE),"")
A14: 112 | B14: BRB | C14: Barbados | D14: Barbados | E14: Caribe | F14: América | G14: América Latina y el Caribe | H14: 1.9238663 | I14: 0 | J14: 3.9324727 | K14: 1.754386 | L14: 0.95242857 | M14: 0 | N14: 9.9623333 | O14: Alto | P14: Alto | Q14: Muy alto | R14: =XLOOKUP(max(L14:N14),L14:N14,$L$2:$N$2,"",0) -> cap | S14: =IFERROR(__xludf.DUMMYFUNCTION("IF(query(Data!A:M,CONCATENATE(""select Col13 where Col1 = '"",C14,""' and Col8 = 'Bias and Unfair Discrimination'""),0)>70,1,0)"),"#REF!") -> #REF! | T14: =IFERROR(__xludf.DUMMYFUNCTION("IF(query(Data!A:M,CONCATENATE(""select Col13 where Col1 = '"",C14,""' and Col8 = 'Childrens Rights'""),0)>70,1,0)"),"#REF!") -> #REF! | U14: =IFERROR(__xludf.DUMMYFUNCTION("IF(query(Data!A:M,CONCATENATE(""select Col13 where Col1 = '"",C14,""' and Col8 = 'Cultural and Linguistic Diversity'""),0)>70,1,0)"),"#REF!") -> #REF! | V14: =IFERROR(__xludf.DUMMYFUNCTION("IF(query(Data!A:M,CONCATENATE(""select Col13 where Col1 = '"",C14,""' and Col8 = 'Data Protection and Privacy'""),0)>70,1,0)"),"#REF!") -> #REF! | W14: =IFERROR(__xludf.DUMMYFUNCTION("IF(query(Data!A:M,CONCATENATE(""select Col13 where Col1 = '"",C14,""' and Col8 = 'Gender Equality'""),0)>70,1,0)"),"#REF!") -> #REF! | X14: =IFERROR(__xludf.DUMMYFUNCTION("IF(query(Data!A:M,CONCATENATE(""select Col13 where Col1 = '"",C14,""' and Col8 = 'Human Oversight and Determination'""),0)>70,1,0)"),"#REF!") -> #REF! | Y14: =IFERROR(__xludf.DUMMYFUNCTION("IF(query(Data!A:M,CONCATENATE(""select Col13 where Col1 = '"",C14,""' and Col8 = 'Labour Protection and Right to Work'""),0)>70,1,0)"),"#REF!") -> #REF! | Z14: =IFERROR(__xludf.DUMMYFUNCTION("IF(query(Data!A:M,CONCATENATE(""select Col13 where Col1 = '"",C14,""' and Col8 = 'Safety, Accuracy and Reliability'""),0)>70,1,0)"),"#REF!") -> #REF! | AA14: =IFERROR(__xludf.DUMMYFUNCTION("IF(query(Data!A:M,CONCATENATE(""select Col13 where Col1 = '"",C14,""' and Col8 = 'Transparency and Explainability'""),0)>70,1,0)"),"#REF!") -> #REF! | AB14: =COUNTIFS(Data!AF:AF,"1",Data!A:A,C14) -> 0 | AC14: =COUNTIFS(Data!X:X,">0",Data!A:A,C14) -> 0 | AD14: =COUNTIFS(Data!AJ:AJ,"12",Data!A:A,C14) -> 0 | AE14: =COUNTIFS(Data!AJ:AJ,"17",Data!A:A,C14) -> 0 | AF14: =COUNTIFS(Data!Y:Y,">0",Data!A:A,C14) -> 0 | AG14: =IF(COUNTIFS(Data!AO:AO,"1",Data!A:A,C14)>0,"Sí","No") -> No | AH14: =IFERROR(__xludf.DUMMYFUNCTION("IFERROR(query(query(Data!A:BS,CONCATENATE(""select Col50, count(Col49) where Col1 = '"",C14,""' group by Col50"")), CONCATENATE(""select Col1 where Col2 = "",query(query(query(Data!A:BS,CONCATENATE(""select Col50, count(Col49) where Col1 = '"",C14,""' and"&" Col50 <> 'Other' and Col50 is not null group by Col50"")),""select max(Col2)"",0),""Select *"",0),"" limit 1""),0))"),"") | AI14: =IFERROR(VLOOKUP(AH14,ref!$A:$B,2,FALSE),"") | AJ14: =IF(COUNTIFS(Data!BI:BI,"1",Data!A:A,C14)>0,"Sí","No") -> No | AK14: =IFERROR(__xludf.DUMMYFUNCTION("IFERROR(query(query(Data!A:BS,CONCATENATE(""select Col70, count(Col69) where Col1 = '"",C14,""' group by Col70"")), CONCATENATE(""select Col1 where Col2 = "",query(query(query(Data!A:BS,CONCATENATE(""select Col70, count(Col69) where Col1 = '"",C14,""' and"&" Col70 <> 'Other' and Col70 is not null group by Col70"")),""select max(Col2)"",0),""Select *"",0),"" limit 1""),0))"),"") | AL14: =IFERROR(VLOOKUP(AK14,ref!$A:$B,2,FALSE),"")
A15: 78 | B15: BHR | C15: Bahrain | D15: Baréin | E15: Medio Oriente | F15: Asia | G15: Asia Occidental | H15: 8.7129263 | I15: 9.673949 | J15: 10.957051 | K15: 2.3026316 | L15: 9.3751429 | M15: 5.1541111 | N15: 17.844667 | O15: Alto | P15: Alto | Q15: Muy bajo | R15: =XLOOKUP(max(L15:N15),L15:N15,$L$2:$N$2,"",0) -> cap | S15: =IFERROR(__xludf.DUMMYFUNCTION("IF(query(Data!A:M,CONCATENATE(""select Col13 where Col1 = '"",C15,""' and Col8 = 'Bias and Unfair Discrimination'""),0)>70,1,0)"),"#REF!") -> #REF! | T15: =IFERROR(__xludf.DUMMYFUNCTION("IF(query(Data!A:M,CONCATENATE(""select Col13 where Col1 = '"",C15,""' and Col8 = 'Childrens Rights'""),0)>70,1,0)"),"#REF!") -> #REF! | U15: =IFERROR(__xludf.DUMMYFUNCTION("IF(query(Data!A:M,CONCATENATE(""select Col13 where Col1 = '"",C15,""' and Col8 = 'Cultural and Linguistic Diversity'""),0)>70,1,0)"),"#REF!") -> #REF! | V15: =IFERROR(__xludf.DUMMYFUNCTION("IF(query(Data!A:M,CONCATENATE(""select Col13 where Col1 = '"",C15,""' and Col8 = 'Data Protection and Privacy'""),0)>70,1,0)"),"#REF!") -> #REF! | W15: =IFERROR(__xludf.DUMMYFUNCTION("IF(query(Data!A:M,CONCATENATE(""select Col13 where Col1 = '"",C15,""' and Col8 = 'Gender Equality'""),0)>70,1,0)"),"#REF!") -> #REF! | X15: =IFERROR(__xludf.DUMMYFUNCTION("IF(query(Data!A:M,CONCATENATE(""select Col13 where Col1 = '"",C15,""' and Col8 = 'Human Oversight and Determination'""),0)>70,1,0)"),"#REF!") -> #REF! | Y15: =IFERROR(__xludf.DUMMYFUNCTION("IF(query(Data!A:M,CONCATENATE(""select Col13 where Col1 = '"",C15,""' and Col8 = 'Labour Protection and Right to Work'""),0)>70,1,0)"),"#REF!") -> #REF! | Z15: =IFERROR(__xludf.DUMMYFUNCTION("IF(query(Data!A:M,CONCATENATE(""select Col13 where Col1 = '"",C15,""' and Col8 = 'Safety, Accuracy and Reliability'""),0)>70,1,0)"),"#REF!") -> #REF! | AA15: =IFERROR(__xludf.DUMMYFUNCTION("IF(query(Data!A:M,CONCATENATE(""select Col13 where Col1 = '"",C15,""' and Col8 = 'Transparency and Explainability'""),0)>70,1,0)"),"#REF!") -> #REF! | AB15: =COUNTIFS(Data!AF:AF,"1",Data!A:A,C15) -> 0 | AC15: =COUNTIFS(Data!X:X,">0",Data!A:A,C15) -> 0 | AD15: =COUNTIFS(Data!AJ:AJ,"12",Data!A:A,C15) -> 0 | AE15: =COUNTIFS(Data!AJ:AJ,"17",Data!A:A,C15) -> 0 | AF15: =COUNTIFS(Data!Y:Y,">0",Data!A:A,C15) -> 0 | AG15: =IF(COUNTIFS(Data!AO:AO,"1",Data!A:A,C15)>0,"Sí","No") -> No | AH15: =IFERROR(__xludf.DUMMYFUNCTION("IFERROR(query(query(Data!A:BS,CONCATENATE(""select Col50, count(Col49) where Col1 = '"",C15,""' group by Col50"")), CONCATENATE(""select Col1 where Col2 = "",query(query(query(Data!A:BS,CONCATENATE(""select Col50, count(Col49) where Col1 = '"",C15,""' and"&" Col50 <> 'Other' and Col50 is not null group by Col50"")),""select max(Col2)"",0),""Select *"",0),"" limit 1""),0))"),"") | AI15: =IFERROR(VLOOKUP(AH15,ref!$A:$B,2,FALSE),"") | AJ15: =IF(COUNTIFS(Data!BI:BI,"1",Data!A:A,C15)>0,"Sí","No") -> No | AK15: =IFERROR(__xludf.DUMMYFUNCTION("IFERROR(query(query(Data!A:BS,CONCATENATE(""select Col70, count(Col69) where Col1 = '"",C15,""' group by Col70"")), CONCATENATE(""select Col1 where Col2 = "",query(query(query(Data!A:BS,CONCATENATE(""select Col70, count(Col69) where Col1 = '"",C15,""' and"&" Col70 <> 'Other' and Col70 is not null group by Col70"")),""select max(Col2)"",0),""Select *"",0),"" limit 1""),0))"),"") | AL15: =IFERROR(VLOOKUP(AK15,ref!$A:$B,2,FALSE),"")
A16: 24 | B16: BEL | C16: Belgium | D16: Bélgica | E16: Europa | F16: Europa | G16: Europa Occidental | H16: 38.54566 | I16: 57.236842 | J16: 27.134434 | K16: 23.985746 | L16: 40.353143 | M16: 41.619333 | N16: 25.107 | O16: Muy alto | P16: Muy alto | Q16: Muy alto | R16: =XLOOKUP(max(L16:N16),L16:N16,$L$2:$N$2,"",0) -> gob | S16: =IFERROR(__xludf.DUMMYFUNCTION("IF(query(Data!A:M,CONCATENATE(""select Col13 where Col1 = '"",C16,""' and Col8 = 'Bias and Unfair Discrimination'""),0)>70,1,0)"),"#REF!") -> #REF! | T16: =IFERROR(__xludf.DUMMYFUNCTION("IF(query(Data!A:M,CONCATENATE(""select Col13 where Col1 = '"",C16,""' and Col8 = 'Childrens Rights'""),0)>70,1,0)"),"#REF!") -> #REF! | U16: =IFERROR(__xludf.DUMMYFUNCTION("IF(query(Data!A:M,CONCATENATE(""select Col13 where Col1 = '"",C16,""' and Col8 = 'Cultural and Linguistic Diversity'""),0)>70,1,0)"),"#REF!") -> #REF! | V16: =IFERROR(__xludf.DUMMYFUNCTION("IF(query(Data!A:M,CONCATENATE(""select Col13 where Col1 = '"",C16,""' and Col8 = 'Data Protection and Privacy'""),0)>70,1,0)"),"#REF!") -> #REF! | W16: =IFERROR(__xludf.DUMMYFUNCTION("IF(query(Data!A:M,CONCATENATE(""select Col13 where Col1 = '"",C16,""' and Col8 = 'Gender Equality'""),0)>70,1,0)"),"#REF!") -> #REF! | X16: =IFERROR(__xludf.DUMMYFUNCTION("IF(query(Data!A:M,CONCATENATE(""select Col13 where Col1 = '"",C16,""' and Col8 = 'Human Oversight and Determination'""),0)>70,1,0)"),"#REF!") -> #REF! | Y16: =IFERROR(__xludf.DUMMYFUNCTION("IF(query(Data!A:M,CONCATENATE(""select Col13 where Col1 = '"",C16,""' and Col8 = 'Labour Protection and Right to Work'""),0)>70,1,0)"),"#REF!") -> #REF! | Z16: =IFERROR(__xludf.DUMMYFUNCTION("IF(query(Data!A:M,CONCATENATE(""select Col13 where Col1 = '"",C16,""' and Col8 = 'Safety, Accuracy and Reliability'""),0)>70,1,0)"),"#REF!") -> #REF! | AA16: =IFERROR(__xludf.DUMMYFUNCTION("IF(query(Data!A:M,CONCATENATE(""select Col13 where Col1 = '"",C16,""' and Col8 = 'Transparency and Explainability'""),0)>70,1,0)"),"#REF!") -> #REF! | AB16: =COUNTIFS(Data!AF:AF,"1",Data!A:A,C16) -> 0 | AC16: =COUNTIFS(Data!X:X,">0",Data!A:A,C16) -> 0 | AD16: =COUNTIFS(Data!AJ:AJ,"12",Data!A:A,C16) -> 0 | AE16: =COUNTIFS(Data!AJ:AJ,"17",Data!A:A,C16) -> 0 | AF16: =COUNTIFS(Data!Y:Y,">0",Data!A:A,C16) -> 0 | AG16: =IF(COUNTIFS(Data!AO:AO,"1",Data!A:A,C16)>0,"Sí","No") -> No | AH16: =IFERROR(__xludf.DUMMYFUNCTION("IFERROR(query(query(Data!A:BS,CONCATENATE(""select Col50, count(Col49) where Col1 = '"",C16,""' group by Col50"")), CONCATENATE(""select Col1 where Col2 = "",query(query(query(Data!A:BS,CONCATENATE(""select Col50, count(Col49) where Col1 = '"",C16,""' and"&" Col50 <> 'Other' and Col50 is not null group by Col50"")),""select max(Col2)"",0),""Select *"",0),"" limit 1""),0))"),"") | AI16: =IFERROR(VLOOKUP(AH16,ref!$A:$B,2,FALSE),"") | AJ16: =IF(COUNTIFS(Data!BI:BI,"1",Data!A:A,C16)>0,"Sí","No") -> No | AK16: =IFERROR(__xludf.DUMMYFUNCTION("IFERROR(query(query(Data!A:BS,CONCATENATE(""select Col70, count(Col69) where Col1 = '"",C16,""' group by Col70"")), CONCATENATE(""select Col1 where Col2 = "",query(query(query(Data!A:BS,CONCATENATE(""select Col70, count(Col69) where Col1 = '"",C16,""' and"&" Col70 <> 'Other' and Col70 is not null group by Col70"")),""select max(Col2)"",0),""Select *"",0),"" limit 1""),0))"),"") | AL16: =IFERROR(VLOOKUP(AK16,ref!$A:$B,2,FALSE),"")
A17: 102 | B17: BLZ | C17: Belize | D17: Belice | E17: Caribe | F17: América | G17: América Latina y el Caribe | H17: 3.2208292 | I17: 0 | J17: 8.0520731 | K17: 0 | L17: 2.9141429 | M17: 2.2665556 | N17: 6.7996667 | O17: Bajo | P17: Medio | Q17: Muy alto | R17: =XLOOKUP(max(L17:N17),L17:N17,$L$2:$N$2,"",0) -> cap | S17: =IFERROR(__xludf.DUMMYFUNCTION("IF(query(Data!A:M,CONCATENATE(""select Col13 where Col1 = '"",C17,""' and Col8 = 'Bias and Unfair Discrimination'""),0)>70,1,0)"),"#REF!") -> #REF! | T17: =IFERROR(__xludf.DUMMYFUNCTION("IF(query(Data!A:M,CONCATENATE(""select Col13 where Col1 = '"",C17,""' and Col8 = 'Childrens Rights'""),0)>70,1,0)"),"#REF!") -> #REF! | U17: =IFERROR(__xludf.DUMMYFUNCTION("IF(query(Data!A:M,CONCATENATE(""select Col13 where Col1 = '"",C17,""' and Col8 = 'Cultural and Linguistic Diversity'""),0)>70,1,0)"),"#REF!") -> #REF! | V17: =IFERROR(__xludf.DUMMYFUNCTION("IF(query(Data!A:M,CONCATENATE(""select Col13 where Col1 = '"",C17,""' and Col8 = 'Data Protection and Privacy'""),0)>70,1,0)"),"#REF!") -> #REF! | W17: =IFERROR(__xludf.DUMMYFUNCTION("IF(query(Data!A:M,CONCATENATE(""select Col13 where Col1 = '"",C17,""' and Col8 = 'Gender Equality'""),0)>70,1,0)"),"#REF!") -> #REF! | X17: =IFERROR(__xludf.DUMMYFUNCTION("IF(query(Data!A:M,CONCATENATE(""select Col13 where Col1 = '"",C17,""' and Col8 = 'Human Oversight and Determination'""),0)>70,1,0)"),"#REF!") -> #REF! | Y17: =IFERROR(__xludf.DUMMYFUNCTION("IF(query(Data!A:M,CONCATENATE(""select Col13 where Col1 = '"",C17,""' and Col8 = 'Labour Protection and Right to Work'""),0)>70,1,0)"),"#REF!") -> #REF! | Z17: =IFERROR(__xludf.DUMMYFUNCTION("IF(query(Data!A:M,CONCATENATE(""select Col13 where Col1 = '"",C17,""' and Col8 = 'Safety, Accuracy and Reliability'""),0)>70,1,0)"),"#REF!") -> #REF! | AA17: =IFERROR(__xludf.DUMMYFUNCTION("IF(query(Data!A:M,CONCATENATE(""select Col13 where Col1 = '"",C17,""' and Col8 = 'Transparency and Explainability'""),0)>70,1,0)"),"#REF!") -> #REF! | AB17: =COUNTIFS(Data!AF:AF,"1",Data!A:A,C17) -> 0 | AC17: =COUNTIFS(Data!X:X,">0",Data!A:A,C17) -> 0 | AD17: =COUNTIFS(Data!AJ:AJ,"12",Data!A:A,C17) -> 0 | AE17: =COUNTIFS(Data!AJ:AJ,"17",Data!A:A,C17) -> 0 | AF17: =COUNTIFS(Data!Y:Y,">0",Data!A:A,C17) -> 0 | AG17: =IF(COUNTIFS(Data!AO:AO,"1",Data!A:A,C17)>0,"Sí","No") -> No | AH17: =IFERROR(__xludf.DUMMYFUNCTION("IFERROR(query(query(Data!A:BS,CONCATENATE(""select Col50, count(Col49) where Col1 = '"",C17,""' group by Col50"")), CONCATENATE(""select Col1 where Col2 = "",query(query(query(Data!A:BS,CONCATENATE(""select Col50, count(Col49) where Col1 = '"",C17,""' and"&" Col50 <> 'Other' and Col50 is not null group by Col50"")),""select max(Col2)"",0),""Select *"",0),"" limit 1""),0))"),"") | AI17: =IFERROR(VLOOKUP(AH17,ref!$A:$B,2,FALSE),"") | AJ17: =IF(COUNTIFS(Data!BI:BI,"1",Data!A:A,C17)>0,"Sí","No") -> No | AK17: =IFERROR(__xludf.DUMMYFUNCTION("IFERROR(query(query(Data!A:BS,CONCATENATE(""select Col70, count(Col69) where Col1 = '"",C17,""' group by Col70"")), CONCATENATE(""select Col1 where Col2 = "",query(query(query(Data!A:BS,CONCATENATE(""select Col70, count(Col69) where Col1 = '"",C17,""' and"&" Col70 <> 'Other' and Col70 is not null group by Col70"")),""select max(Col2)"",0),""Select *"",0),"" limit 1""),0))"),"") | AL17: =IFERROR(VLOOKUP(AK17,ref!$A:$B,2,FALSE),"")
A18: 53 | B18: BEN | C18: Benin | D18: Benín | E18: África | F18: África | G18: África Subsahariana | H18: 21.958768 | I18: 16.882862 | J18: 22.183466 | K18: 31.661184 | L18: 19.024571 | M18: 22.241444 | N18: 27.957333 | O18: Medio | P18: Alto | Q18: Muy alto | R18: =XLOOKUP(max(L18:N18),L18:N18,$L$2:$N$2,"",0) -> cap | S18: =IFERROR(__xludf.DUMMYFUNCTION("IF(query(Data!A:M,CONCATENATE(""select Col13 where Col1 = '"",C18,""' and Col8 = 'Bias and Unfair Discrimination'""),0)>70,1,0)"),"#REF!") -> #REF! | T18: =IFERROR(__xludf.DUMMYFUNCTION("IF(query(Data!A:M,CONCATENATE(""select Col13 where Col1 = '"",C18,""' and Col8 = 'Childrens Rights'""),0)>70,1,0)"),"#REF!") -> #REF! | U18: =IFERROR(__xludf.DUMMYFUNCTION("IF(query(Data!A:M,CONCATENATE(""select Col13 where Col1 = '"",C18,""' and Col8 = 'Cultural and Linguistic Diversity'""),0)>70,1,0)"),"#REF!") -> #REF! | V18: =IFERROR(__xludf.DUMMYFUNCTION("IF(query(Data!A:M,CONCATENATE(""select Col13 where Col1 = '"",C18,""' and Col8 = 'Data Protection and Privacy'""),0)>70,1,0)"),"#REF!") -> #REF! | W18: =IFERROR(__xludf.DUMMYFUNCTION("IF(query(Data!A:M,CONCATENATE(""select Col13 where Col1 = '"",C18,""' and Col8 = 'Gender Equality'""),0)>70,1,0)"),"#REF!") -> #REF! | X18: =IFERROR(__xludf.DUMMYFUNCTION("IF(query(Data!A:M,CONCATENATE(""select Col13 where Col1 = '"",C18,""' and Col8 = 'Human Oversight and Determination'""),0)>70,1,0)"),"#REF!") -> #REF! | Y18: =IFERROR(__xludf.DUMMYFUNCTION("IF(query(Data!A:M,CONCATENATE(""select Col13 where Col1 = '"",C18,""' and Col8 = 'Labour Protection and Right to Work'""),0)>70,1,0)"),"#REF!") -> #REF! | Z18: =IFERROR(__xludf.DUMMYFUNCTION("IF(query(Data!A:M,CONCATENATE(""select Col13 where Col1 = '"",C18,""' and Col8 = 'Safety, Accuracy and Reliability'""),0)>70,1,0)"),"#REF!") -> #REF! | AA18: =IFERROR(__xludf.DUMMYFUNCTION("IF(query(Data!A:M,CONCATENATE(""select Col13 where Col1 = '"",C18,""' and Col8 = 'Transparency and Explainability'""),0)>70,1,0)"),"#REF!") -> #REF! | AB18: =COUNTIFS(Data!AF:AF,"1",Data!A:A,C18) -> 0 | AC18: =COUNTIFS(Data!X:X,">0",Data!A:A,C18) -> 0 | AD18: =COUNTIFS(Data!AJ:AJ,"12",Data!A:A,C18) -> 0 | AE18: =COUNTIFS(Data!AJ:AJ,"17",Data!A:A,C18) -> 0 | AF18: =COUNTIFS(Data!Y:Y,">0",Data!A:A,C18) -> 0 | AG18: =IF(COUNTIFS(Data!AO:AO,"1",Data!A:A,C18)>0,"Sí","No") -> No | AH18: =IFERROR(__xludf.DUMMYFUNCTION("IFERROR(query(query(Data!A:BS,CONCATENATE(""select Col50, count(Col49) where Col1 = '"",C18,""' group by Col50"")), CONCATENATE(""select Col1 where Col2 = "",query(query(query(Data!A:BS,CONCATENATE(""select Col50, count(Col49) where Col1 = '"",C18,""' and"&" Col50 <> 'Other' and Col50 is not null group by Col50"")),""select max(Col2)"",0),""Select *"",0),"" limit 1""),0))"),"") | AI18: =IFERROR(VLOOKUP(AH18,ref!$A:$B,2,FALSE),"") | AJ18: =IF(COUNTIFS(Data!BI:BI,"1",Data!A:A,C18)>0,"Sí","No") -> No | AK18: =IFERROR(__xludf.DUMMYFUNCTION("IFERROR(query(query(Data!A:BS,CONCATENATE(""select Col70, count(Col69) where Col1 = '"",C18,""' group by Col70"")), CONCATENATE(""select Col1 where Col2 = "",query(query(query(Data!A:BS,CONCATENATE(""select Col70, count(Col69) where Col1 = '"",C18,""' and"&" Col70 <> 'Other' and Col70 is not null group by Col70"")),""select max(Col2)"",0),""Select *"",0),"" limit 1""),0))"),"") | AL18: =IFERROR(VLOOKUP(AK18,ref!$A:$B,2,FALSE),"")
A19: 110 | B19: BLR | C19: Belarus | D19: Bielorrusia | E19: Europa | F19: Europa | G19: Europa del Este | H19: 2.0617759 | I19: 0 | J19: 4.1950099 | K19: 1.9188596 | L19: 0.26042857 | M19: 2.1763333 | N19: 5.9213333 | O19: Muy bajo | P19: Bajo | Q19: Muy bajo | R19: =XLOOKUP(max(L19:N19),L19:N19,$L$2:$N$2,"",0) -> cap | S19: =IFERROR(__xludf.DUMMYFUNCTION("IF(query(Data!A:M,CONCATENATE(""select Col13 where Col1 = '"",C19,""' and Col8 = 'Bias and Unfair Discrimination'""),0)>70,1,0)"),"#REF!") -> #REF! | T19: =IFERROR(__xludf.DUMMYFUNCTION("IF(query(Data!A:M,CONCATENATE(""select Col13 where Col1 = '"",C19,""' and Col8 = 'Childrens Rights'""),0)>70,1,0)"),"#REF!") -> #REF! | U19: =IFERROR(__xludf.DUMMYFUNCTION("IF(query(Data!A:M,CONCATENATE(""select Col13 where Col1 = '"",C19,""' and Col8 = 'Cultural and Linguistic Diversity'""),0)>70,1,0)"),"#REF!") -> #REF! | V19: =IFERROR(__xludf.DUMMYFUNCTION("IF(query(Data!A:M,CONCATENATE(""select Col13 where Col1 = '"",C19,""' and Col8 = 'Data Protection and Privacy'""),0)>70,1,0)"),"#REF!") -> #REF! | W19: =IFERROR(__xludf.DUMMYFUNCTION("IF(query(Data!A:M,CONCATENATE(""select Col13 where Col1 = '"",C19,""' and Col8 = 'Gender Equality'""),0)>70,1,0)"),"#REF!") -> #REF! | X19: =IFERROR(__xludf.DUMMYFUNCTION("IF(query(Data!A:M,CONCATENATE(""select Col13 where Col1 = '"",C19,""' and Col8 = 'Human Oversight and Determination'""),0)>70,1,0)"),"#REF!") -> #REF! | Y19: =IFERROR(__xludf.DUMMYFUNCTION("IF(query(Data!A:M,CONCATENATE(""select Col13 where Col1 = '"",C19,""' and Col8 = 'Labour Protection and Right to Work'""),0)>70,1,0)"),"#REF!") -> #REF! | Z19: =IFERROR(__xludf.DUMMYFUNCTION("IF(query(Data!A:M,CONCATENATE(""select Col13 where Col1 = '"",C19,""' and Col8 = 'Safety, Accuracy and Reliability'""),0)>70,1,0)"),"#REF!") -> #REF! | AA19: =IFERROR(__xludf.DUMMYFUNCTION("IF(query(Data!A:M,CONCATENATE(""select Col13 where Col1 = '"",C19,""' and Col8 = 'Transparency and Explainability'""),0)>70,1,0)"),"#REF!") -> #REF! | AB19: =COUNTIFS(Data!AF:AF,"1",Data!A:A,C19) -> 0 | AC19: =COUNTIFS(Data!X:X,">0",Data!A:A,C19) -> 0 | AD19: =COUNTIFS(Data!AJ:AJ,"12",Data!A:A,C19) -> 0 | AE19: =COUNTIFS(Data!AJ:AJ,"17",Data!A:A,C19) -> 0 | AF19: =COUNTIFS(Data!Y:Y,">0",Data!A:A,C19) -> 0 | AG19: =IF(COUNTIFS(Data!AO:AO,"1",Data!A:A,C19)>0,"Sí","No") -> No | AH19: =IFERROR(__xludf.DUMMYFUNCTION("IFERROR(query(query(Data!A:BS,CONCATENATE(""select Col50, count(Col49) where Col1 = '"",C19,""' group by Col50"")), CONCATENATE(""select Col1 where Col2 = "",query(query(query(Data!A:BS,CONCATENATE(""select Col50, count(Col49) where Col1 = '"",C19,""' and"&" Col50 <> 'Other' and Col50 is not null group by Col50"")),""select max(Col2)"",0),""Select *"",0),"" limit 1""),0))"),"") | AI19: =IFERROR(VLOOKUP(AH19,ref!$A:$B,2,FALSE),"") | AJ19: =IF(COUNTIFS(Data!BI:BI,"1",Data!A:A,C19)>0,"Sí","No") -> No | AK19: =IFERROR(__xludf.DUMMYFUNCTION("IFERROR(query(query(Data!A:BS,CONCATENATE(""select Col70, count(Col69) where Col1 = '"",C19,""' group by Col70"")), CONCATENATE(""select Col1 where Col2 = "",query(query(query(Data!A:BS,CONCATENATE(""select Col70, count(Col69) where Col1 = '"",C19,""' and"&" Col70 <> 'Other' and Col70 is not null group by Col70"")),""select max(Col2)"",0),""Select *"",0),"" limit 1""),0))"),"") | AL19: =IFERROR(VLOOKUP(AK19,ref!$A:$B,2,FALSE),"")
